<?xml version = "1.0"?>
<robot name ="unodopo" xmlns:controller="http://playerstage.sourceforge.net/gazebo/xmlschema/#controller"
  xmlns:interface="http://playerstage.sourceforge.net/gazebo/xmlschema/#interface"
  xmlns:sensor="http://playerstage.sourceforge.net/gazebo/xmlschema/#sensor"
  xmlns:xacro="http://ros.org/wiki/xacro">

    <xacro:property name="wheel_offset" value="0.037465" /> <!--wheel pivot offset from origin-->
    <xacro:macro name="lame_inertia">
        <inertia ixx="0.1" ixy = "0" ixz = "0"
                iyy="0.1" iyz = "0"
                izz="0.1" /> 
    </xacro:macro>

    <xacro:include filename="$(find unodopo_description)/urdf/accessories/sick_scan.urdf.xacro"/>
    <xacro:sick_tim_57x name="laser" ros_topic="laser_scan" visualize="false" wheel_offset="${wheel_offset}"/>
    <!-- <xacro:include filename="$(find unodopo_description)/urdf/accessories/test.xacro"/> -->



    <material name = "blue">
        <color rgba="0 0 0.8 1"/>
    </material>

    <material name = "white">
        <color rgba="1 1 1 1"/>
    </material>

    <material name = "yellow">
        <color rgba="1 0.964 0.321 1"/>
    </material>

    <material name ="purple">
        <color rgba="0.933 0.321 1 1"/>
    </material>


    <xacro:property name="base_width" value="0.44" /> 
    <xacro:property name="base_height" value="0.3" /> 
    <xacro:property name="base_depth" value="0.62" /> <!-- in m-->
    <xacro:property name="base_mass" value="30" /> <!-- in kg-->
    
    <xacro:property name="caster_wheel_radius" value="0.02" /> 
    <xacro:property name="caster_wheel_mass" value="0.5" /> <!-- in kg-->
    <xacro:property name="caster_wheel_height" value="0.02"/>

    <xacro:property name="wheel_radius" value="0.155" /> 
    <xacro:property name="wheel_mass" value="5" /> <!-- in kg-->
    <xacro:property name="wheel_height" value="0.05"/>
    <xacro:property name="wheel_separation" value="0.32"/>
    <xacro:property name="wheel_friction" value="1"/>

    <xacro:property name="caster_wheel_friction" value="0.1"/>
    <xacro:property name="caster_mount_friction" value="0.3"/>


   
      <!-- Macro for calculating inertia of cylinder -->
    <xacro:macro name="cylinder_inertia" params="m r h">
        <inertia ixx="${m*(3*r*r+h*h)/12}" ixy = "0" ixz = "0"
                iyy="${m*(3*r*r+h*h)/12}" iyz = "0"
                izz="${m*r*r/2}" /> 
    </xacro:macro>

    <xacro:macro name="cuboid_inertia" params="m w h d">
        <inertia ixx="${m*(h*h+d*d)/12}" ixy = "0" ixz = "0"
                iyy="${m*(w*w+d*d)/12}" iyz = "0"
                izz="${m*(w*w+h*h)/12}" /> 
    </xacro:macro>


    <link name="base_footprint">
        <origin rpy="0 0 0" xyz="0 0 0"/>
    </link>

    <joint name="base_joint" type="fixed">
        <origin xyz="0 0 -${wheel_offset}" rpy="0 0 0"/>
        <parent link="base_link"/>
        <child link="base_footprint"/>
      </joint>

    <link name = "base_link">
        <visual>
            <geometry>
               <mesh filename="package://unodopo_description/meshes/unodopo_main_body.stl" scale="0.001 0.001 0.001"/> <!-- converting from mm to m--> 
            </geometry>
            <origin xyz="0 0 -${wheel_offset}"/>
            <material name ="yellow"/> 
        </visual>
        <collision>
            <geometry>
               <mesh filename="package://unodopo_description/meshes/unodopo_main_body.stl" scale="0.001 0.001 0.001"/> 
            </geometry>
            <origin xyz="0 0 -${wheel_offset}"/>
        </collision>
        <inertial>
            <mass value="${base_mass}" />
            <origin xyz="0 0 -${wheel_offset}"/>
            <xacro:cuboid_inertia m="${base_mass}" w="${base_width}" h="${base_height}" d="${base_depth}"/>
        </inertial>
    </link>
    <gazebo reference="base_link">
        <material>Gazebo/Orange</material>
        <kp>10000000</kp>
        <kd>1.0</kd>
         
        <minDepth>0.001</minDepth>

    </gazebo>

    <link name ="right_wheel">
        <visual>
            <geometry>
               <mesh filename="package://unodopo_description/meshes/unodopo_right_wheel.stl" scale="0.001 0.001 0.001"/> 
            </geometry>
            <origin xyz="0 0 -${wheel_offset}"/>
            <material name="white"/>
        </visual>
        <collision>
            <geometry>
               <mesh filename="package://unodopo_description/meshes/unodopo_right_wheel.stl" scale="0.001 0.001 0.001"/> 
            </geometry>
            <origin xyz="0 0 -${wheel_offset}"/>
        </collision>
        <inertial>
            <mass value="${wheel_mass}"/>
            <origin xyz="0 0 -${wheel_offset}"/>
            <xacro:cylinder_inertia m="${wheel_mass}" r="${wheel_radius}" h="${wheel_height}"/>
        </inertial>
    </link>
    <gazebo reference="right_wheel">
        <material>Gazebo/White</material>
        <kp>10000000</kp>
        <kd>1.0</kd>
        <mu1 value ="${wheel_friction}"/>
        <mu2 value ="${wheel_friction}"/>
        <maxVel>1</maxVel>
        <minDepth>0.001</minDepth>


    </gazebo>

    <joint name="right_wheel_joint" type ="continuous">
        <parent link ="base_link"/>
        <child link="right_wheel"/>
        <origin xyz="0 0 0.004"/>
        <axis xyz="0 1 0"/>
    </joint>

    <link name="left_wheel">
        <visual>
            <geometry>
               <mesh filename="package://unodopo_description/meshes/unodopo_left_wheel.stl" scale="0.001 0.001 0.001"/> 
            </geometry>
            <origin xyz="0 0 -${wheel_offset}"/>
            <material name="white"/>
        </visual>
        <collision>
            <geometry>
               <mesh filename="package://unodopo_description/meshes/unodopo_left_wheel.stl" scale="0.001 0.001 0.001"/> 
            </geometry>
            <origin xyz="0 0 -${wheel_offset}"/>
        </collision>
        <inertial>
            <mass value="${wheel_mass}"/>
            <origin xyz="0 0 -${wheel_offset}"/>
            <xacro:cylinder_inertia m="${wheel_mass}" r="${wheel_radius}" h="${wheel_height}"/>
        </inertial>
    </link>
    <gazebo reference="left_wheel">
        <material>Gazebo/White</material>
        <kp>10000000</kp>
        <kd>1.0</kd>
        <mu1 value ="${wheel_friction}"/>
        <mu2 value ="${wheel_friction}"/>
        <maxVel>1</maxVel>
        <minDepth>0.001</minDepth>

    </gazebo>

    <joint name="left_wheel_joint" type="continuous">
       <parent link="base_link"/> 
       <child link="left_wheel"/>
        <origin xyz="0 0 0.004"/>
       <axis xyz="0 1 0"/>
    </joint>
    
<!-- lidar-->

    <!-- <link name="laser_mount_link">
        <visual>
            <geometry>
                <mesh filename="package://unodopo_description/meshes/accessories/sick_tim571.stl" scale="0.001 0.001 0.001" />
            </geometry>
            <origin xyz="0 0 -${wheel_offset}"/>
        </visual>
        <collision>
            <geometry>
                <mesh filename="package://unodopo_description/meshes/accessories/sick_tim571.stl" scale="0.001 0.001 0.001"/>
            </geometry>
            <origin xyz="0 0 -${wheel_offset}"/> 
        </collision>
        <inertial>
            <mass value="0.01"/>
            <origin xyz="0 0 -${wheel_offset}"/>
            <xacro:lame_inertia/>
        </inertial>
    </link>
    <joint name="laser_joint" type="fixed">
        <origin xyz="0 0 0"/>
        <parent link="base_link"/>
        <child link="laser_mount_link"/>
    </joint> -->

<!-- caster front left-->

    <link name="caster_mount_frontleft">
        <visual>
            <geometry>
               <mesh filename="package://unodopo_description/meshes/accessories/caster_mount_frontleft.stl" scale="0.001 0.001 0.001"/> 
            </geometry>
            <origin xyz="0.210 0.120 ${0.040-wheel_offset}"/>
            <material name="blue"/>
        </visual>
        <collision>
            <geometry>
                <sphere radius="0.005"/>
            </geometry>
            <origin xyz="0 0 0"/>
        </collision>
        <inertial>
            <mass value="0.1"/>
            <origin xyz="0.210 0.120 ${0.040-wheel_offset}"/>
            <xacro:lame_inertia/>
        </inertial>
    </link>
    <gazebo reference="caster_mount_frontleft">
        <kp>10000000</kp>
        <kd>1.0</kd>
        <material>Gazebo/Green</material>
        <mu1 value ="${caster_mount_friction}"/>
        <mu2 value ="${caster_mount_friction}"/>
         
        <minDepth>0.001</minDepth>
    </gazebo>

    <joint name="caster_mount_frontleft_joint" type="continuous">
       <parent link="base_link"/> 
       <child link="caster_mount_frontleft"/>
       <origin xyz="-0.210 -0.120 -0.040"/>
       <axis xyz="0 0 1"/>
    </joint>

    <link name="caster_wheel_frontleft">
        <visual>
            <geometry>
               <mesh filename="package://unodopo_description/meshes/accessories/caster_wheel_frontleft.stl" scale="0.001 0.001 0.001"/> 
            </geometry>
            <origin xyz="0.196 0.120 ${0.072-wheel_offset}"/>
            <material name="purple"/>
        </visual>
        <collision>
            <geometry>
                <cylinder length="0.02" radius="0.025"/>            
            </geometry>
            <origin xyz="0 0 0" rpy="${pi/2} 0 0"/>
        </collision>
        <inertial>
            <mass value="${caster_wheel_mass}"/>
            <origin xyz="0.196 0.120 ${0.072-wheel_offset}"/>
            <xacro:cylinder_inertia m="${caster_wheel_mass}" r="${caster_wheel_radius}" h="${caster_wheel_height}"/>
        </inertial>
    </link>
    <gazebo reference="caster_wheel_frontleft">
        <material>Gazebo/Blue</material>
        <kp>10000000</kp>
        <kd>1.0</kd>
        <mu1 value ="${caster_wheel_friction}"/>
        <mu2 value ="${caster_wheel_friction}"/>
         
        <minDepth>0.001</minDepth>


    </gazebo>

    <joint name="caster_wheel_frontleft_joint" type="continuous">
       <parent link="caster_mount_frontleft"/> 
       <child link="caster_wheel_frontleft"/>
       <origin xyz="0.014 0 ${-0.069+wheel_offset}"/>
       <axis xyz="0 1 0"/>
    </joint> 

<!-- caster front right-->

<link name="caster_mount_frontright">
    <visual>
        <geometry>
           <mesh filename="package://unodopo_description/meshes/accessories/caster_mount_frontright.stl" scale="0.001 0.001 0.001"/> 
        </geometry>
        <origin xyz="0.210 -0.120 ${0.040-wheel_offset}"/>
        <material name="blue"/>
    </visual>
    <collision>
        <geometry>
            <sphere radius="0.005"/>
        </geometry>
        <origin xyz="0 0 0"/>
    </collision>
    <inertial>
        <mass value="0.1"/>
        <origin xyz="0.210 -0.120 ${0.040-wheel_offset}"/>
        <xacro:lame_inertia/>
    </inertial>
</link>
<gazebo reference="caster_mount_frontright">
    <kp>10000000</kp>
    <kd>1.0</kd>
    <material>Gazebo/Green</material>
    <mu1 value ="${caster_mount_friction}"/>
    <mu2 value ="${caster_mount_friction}"/>
     
    <minDepth>0.001</minDepth>
</gazebo>

<joint name="caster_mount_frontright_joint" type="continuous">
   <parent link="base_link"/> 
   <child link="caster_mount_frontright"/>
   <origin xyz="-0.210 0.120 -0.040"/>
   <axis xyz="0 0 1"/>
</joint>

<link name="caster_wheel_frontright">
    <visual>
        <geometry>
           <mesh filename="package://unodopo_description/meshes/accessories/caster_wheel_frontright.stl" scale="0.001 0.001 0.001"/> 
        </geometry>
        <origin xyz="0.196 -0.120 ${0.072-wheel_offset}"/>
        <material name="purple"/>
    </visual>
    <collision>
        <geometry>
            <cylinder length="0.02" radius="0.025"/>            
        </geometry>
        <origin xyz="0 0 0" rpy="${pi/2} 0 0"/>
    </collision>
    <inertial>
        <mass value="${caster_wheel_mass}"/>
        <origin xyz="0.196 -0.120 ${0.072-wheel_offset}"/>
        <xacro:cylinder_inertia m="${caster_wheel_mass}" r="${caster_wheel_radius}" h="${caster_wheel_height}"/>
    </inertial>
</link>
<gazebo reference="caster_wheel_frontright">
    <kp>10000000</kp>
    <kd>1.0</kd>
    <material>Gazebo/Blue</material>
    <mu1 value ="${caster_wheel_friction}"/>
    <mu2 value ="${caster_wheel_friction}"/>
     
    <minDepth>0.001</minDepth>
</gazebo>

<joint name="caster_wheel_frontright_joint" type="continuous">
   <parent link="caster_mount_frontright"/> 
   <child link="caster_wheel_frontright"/>
   <origin xyz="0.014 0 ${-0.069+wheel_offset}"/>
   <axis xyz="0 1 0"/>
</joint> 

<!-- caster back right-->

<link name="caster_mount_backright">
    <visual>
        <geometry>
           <mesh filename="package://unodopo_description/meshes/accessories/caster_mount_backright.stl" scale="0.001 0.001 0.001"/> 
        </geometry>
        <origin xyz="-0.210 -0.120 ${0.040-wheel_offset}"/>
        <material name="blue"/>
    </visual>
    <collision>
        <geometry>
            <sphere radius="0.005"/>
        </geometry>
        <origin xyz="0 0 0"/>
    </collision>
    <inertial>
        <mass value="0.1"/>
        <origin xyz="-0.210 -0.120 ${0.040-wheel_offset}"/>
        <xacro:lame_inertia/>
    </inertial>
</link>
<gazebo reference="caster_mount_backright">
    <kp>10000000</kp>
    <kd>1.0</kd>
    <material>Gazebo/Green</material>
    <mu1 value ="${caster_mount_friction}"/>
    <mu2 value ="${caster_mount_friction}"/>
     
    <minDepth>0.001</minDepth>
</gazebo>

<joint name="caster_mount_backright_joint" type="continuous">
   <parent link="base_link"/> 
   <child link="caster_mount_backright"/>
   <origin xyz="0.210 0.120 -0.040"/>
   <axis xyz="0 0 1"/>
</joint>

<link name="caster_wheel_backright">
    <visual>
        <geometry>
           <mesh filename="package://unodopo_description/meshes/accessories/caster_wheel_backright.stl" scale="0.001 0.001 0.001"/> 
        </geometry>
        <origin xyz="-0.224 -0.120 ${0.072-wheel_offset}"/>
        <material name="purple"/>
    </visual>
    <collision>
        <geometry>
            <cylinder length="0.02" radius="0.025"/>            
        </geometry>
        <origin xyz="0 0 0" rpy="${pi/2} 0 0"/>
    </collision>
    <inertial>
        <mass value="${caster_wheel_mass}"/>
        <origin xyz="-0.224 -0.120 ${0.072-wheel_offset}"/>
        <xacro:cylinder_inertia m="${caster_wheel_mass}" r="${caster_wheel_radius}" h="${caster_wheel_height}"/>
    </inertial>
</link>
<gazebo reference="caster_wheel_backright">
    <kp>10000000</kp>
    <kd>1.0</kd>
    <material>Gazebo/Blue</material>
    <mu1 value ="${caster_wheel_friction}"/>
    <mu2 value ="${caster_wheel_friction}"/>
     
    <minDepth>0.001</minDepth>


</gazebo>

<joint name="caster_wheel_backright_joint" type="continuous">
   <parent link="caster_mount_backright"/> 
   <child link="caster_wheel_backright"/>
   <origin xyz="0.014 0 ${-0.069+wheel_offset}"/>
   <axis xyz="0 1 0"/>
</joint> 

<!-- caster back left-->

<link name="caster_mount_backleft">
    <visual>
        <geometry>
           <mesh filename="package://unodopo_description/meshes/accessories/caster_mount_backleft.stl" scale="0.001 0.001 0.001"/> 
        </geometry>
        <origin xyz="-0.210 0.120 ${0.040-wheel_offset}"/>
        <material name="blue"/>
    </visual>
    <collision>
        <geometry>
            <sphere radius="0.005"/>
        </geometry>
        <origin xyz="0 0 0"/>
    </collision>
    <inertial>
        <mass value="0.1"/>
        <origin xyz="-0.210 0.120 ${0.040-wheel_offset}"/>
        <xacro:lame_inertia/>
    </inertial>
</link>
<gazebo reference="caster_mount_backleft">
    <kp>10000000</kp>
    <kd>1.0</kd>
    <material>Gazebo/Green</material>
    <mu1 value ="${caster_mount_friction}"/>
    <mu2 value ="${caster_mount_friction}"/>
     
    <minDepth>0.001</minDepth>
</gazebo>

<joint name="caster_mount_backleft_joint" type="continuous">
   <parent link="base_link"/> 
   <child link="caster_mount_backleft"/>
   <origin xyz="0.210 -0.120 -0.040"/>
   <axis xyz="0 0 1"/>
</joint>

<link name="caster_wheel_backleft">
    <visual>
        <geometry>
           <mesh filename="package://unodopo_description/meshes/accessories/caster_wheel_backleft.stl" scale="0.001 0.001 0.001"/> 
        </geometry>
        <origin xyz="-0.224 0.120 ${0.072-wheel_offset}"/>
        <material name="purple"/>
    </visual>
    <collision>
        <geometry>
            <cylinder length="0.02" radius="0.025"/>            
        </geometry>
        <origin xyz="0 0 0" rpy="${pi/2} 0 0"/>
    </collision>
    <inertial>
        <mass value="${caster_wheel_mass}"/>
        <origin xyz="-0.224 0.120 ${0.072-wheel_offset}"/>
        <xacro:cylinder_inertia m="${caster_wheel_mass}" r="${caster_wheel_radius}" h="${caster_wheel_height}"/>
    </inertial>
</link>
<gazebo reference="caster_wheel_backleft">
    <kp>10000000</kp>
    <kd>1.0</kd>
    <material>Gazebo/Blue</material>
    <mu1 value ="${caster_wheel_friction}"/>
    <mu2 value ="${caster_wheel_friction}"/>
     
    <minDepth>0.001</minDepth>


</gazebo>

<joint name="caster_wheel_backleft_joint" type="continuous">
   <parent link="caster_mount_backleft"/> 
   <child link="caster_wheel_backleft"/>
   <origin xyz="0.014 0 ${-0.069+wheel_offset}"/>
   <axis xyz="0 1 0"/>
</joint> 


<xacro:include filename="$(find unodopo_description)/urdf/accessories/gazebo_diff_drive_plugin.xacro"/>


</robot>